Workbook
Name Slicer_CourseName: #N/A
Name Slicer_MentorName: #N/A
Name Slicer_Platform: #N/A

Sheet Dataset
A1: StudentID | B1: StudentName | C1: CourseID | D1: CourseName | E1: BatchID | F1: MentorName | G1: Platform | H1: PaymentAmount | I1: DiscountCode | J1: DiscountPercent | K1: TargetRevenue | L1: PaymentDate
A2: S1000 | B2: Rohit Shah | C2: C201 | D2: Data Analytics | E2: B3 | F2: Priya | G2: Web | H2: 12914 | I2: DISC20 | J2: 0.2 | K2: 14000 | L2: 45339
A3: S1001 | B3: Riya Singh | C3: C201 | D3: Data Analytics | E3: B3 | F3: Priya | G3: Web | H3: 12122 | I3: DISC10 | J3: 0.1 | K3: 14000 | L3: 45305
A4: S1002 | B4: Sneha Gupta | C4: C201 | D4: Data Analytics | E4: B3 | F4: Saurabh | G4: Tablet | H4: 14661 | I4: DISC15 | K4: 14000 | L4: 45318
A5: S1003 | B5: Sneha Iyer | C5: C203 | D5: Full Stack Dev | E5: B1 | F5: Saurabh | G5: Tablet | H5: 16731 | I5: DISC30 | J5: 0.3 | K5: 17000 | L5: 45309
A6: S1004 | B6: Karan Patil | C6: C203 | D6: Full Stack Dev | E6: B1 | F6: Saurabh | G6: Mobile | H6: 15396 | I6: DISC30 | J6: 0.3 | K6: 17000 | L6: 45346
A7: S1005 | B7: Pooja Joshi | C7: C203 | D7: Full Stack Dev | E7: B1 | F7: Amit | G7: Mobile | H7: 17196 | I7: DISC10 | J7: 0.1 | K7: 17000 | L7: 45351
A8: S1006 | B8: Rahul Shah | C8: C203 | D8: Full Stack Dev | E8: B3 | F8: Amit | G8: Mobile | H8: 17364 | I8: DISC20 | J8: 0.2 | K8: 17000 | L8: 45337
A9: S1007 | B9: Riya Kulkarni | C9: C202 | D9: Data Science | E9: B2 | F9: Saurabh | G9: Web | H9: 14549 | I9: DISC10 | J9: 0.1 | K9: 13000 | L9: 45316
A10: S1008 | B10: Aditya Iyer | C10: C203 | D10: Full Stack Dev | E10: B1 | F10: Priya | G10: Mobile | H10: 15858 | I10: DISC30 | J10: 0.3 | K10: 17000 | L10: 45336
A11: S1009 | B11: Kunal Singh | C11: C201 | D11: Data Analytics | E11: B3 | F11: Amit | G11: Web | H11: 14187 | I11: DISC20 | J11: 0.2 | K11: 14000 | L11: 45302
A12: S1010 | B12: Neha Verma | C12: C203 | D12: Full Stack Dev | E12: B3 | F12: Amit | G12: Tablet | H12: 15899 | I12: DISC30 | J12: 0.3 | K12: 17000 | L12: 45345
A13: S1011 | B13: Dev Patel | C13: C201 | D13: Data Analytics | E13: B1 | F13: Saurabh | G13: Mobile | H13: 13643 | I13: DISC30 | J13: 0.3 | K13: 14000 | L13: 45296
A14: S1012 | B14: Sneha Joshi | C14: C203 | D14: Full Stack Dev | E14: B1 | F14: Amit | G14: Mobile | H14: 16620 | K14: 17000 | L14: 45301
A15: S1013 | B15: Aditya Mehta | C15: C202 | D15: Data Science | E15: B3 | F15: Amit | G15: Tablet | H15: 12076 | I15: DISC15 | K15: 13000 | L15: 45319
A16: S1014 | B16: Kunal Joshi | C16: C204 | D16: UI UX Design | E16: B2 | F16: Saurabh | G16: Web | H16: 9087 | K16: 9000 | L16: 45297
A17: S1015 | B17: Dev Kulkarni | C17: C201 | D17: Data Analytics | E17: B1 | F17: Amit | G17: Web | H17: 15244 | K17: 14000 | L17: 45330
A18: S1016 | B18: Riya Verma | C18: C204 | D18: UI UX Design | E18: B3 | F18: Priya | G18: Tablet | H18: 8029 | I18: DISC15 | K18: 9000 | L18: 45347
A19: S1017 | B19: Aarav Singh | C19: C201 | D19: Data Analytics | E19: B3 | F19: Amit | G19: Mobile | H19: 15148 | I19: DISC30 | J19: 0.3 | K19: 14000 | L19: 45299
A20: S1018 | B20: Aditya Verma | C20: C202 | D20: Data Science | E20: B2 | F20: Saurabh | G20: Tablet | H20: 14587 | I20: DISC30 | J20: 0.3 | K20: 13000 | L20: 45324
A21: S1019 | B21: Dev Mehta | C21: C201 | D21: Data Analytics | E21: B3 | F21: Priya | G21: Tablet | H21: 14079 | I21: DISC15 | K21: 14000 | L21: 45304
A22: S1020 | B22: Karan Jain | C22: C202 | D22: Data Science | E22: B3 | F22: Amit | G22: Web | H22: 13453 | I22: DISC30 | J22: 0.3 | K22: 13000 | L22: 45323
A23: S1021 | B23: Aarav Shah | C23: C203 | D23: Full Stack Dev | E23: B2 | F23: Saurabh | G23: Web | H23: 15986 | I23: DISC15 | K23: 17000 | L23: 45352
A24: S1022 | B24: Riya Shah | C24: C204 | D24: UI UX Design | E24: B1 | F24: Amit | G24: Web | H24: 7525 | K24: 9000 | L24: 45352
A25: S1023 | B25: Manish Mehta | C25: C203 | D25: Full Stack Dev | E25: B3 | F25: Amit | G25: Mobile | H25: 18950 | I25: DISC20 | J25: 0.2 | K25: 17000 | L25: 45351
A26: S1024 | B26: Manish Patel | C26: C202 | D26: Data Science | E26: B3 | F26: Priya | G26: Mobile | H26: 13751 | I26: DISC30 | J26: 0.3 | K26: 13000 | L26: 45320
A27: S1025 | B27: Kunal Gupta | C27: C204 | D27: UI UX Design | E27: B1 | F27: Saurabh | G27: Web | H27: 7262 | I27: DISC30 | J27: 0.3 | K27: 9000 | L27: 45293
A28: S1026 | B28: Kavita Gupta | C28: C202 | D28: Data Science | E28: B3 | F28: Saurabh | G28: Web | H28: 11290 | I28: DISC10 | J28: 0.1 | K28: 13000 | L28: 45306
A29: S1027 | B29: Riya Kulkarni | C29: C203 | D29: Full Stack Dev | E29: B1 | F29: Amit | G29: Web | H29: 16140 | K29: 17000 | L29: 45305
A30: S1028 | B30: Manish Mehta | C30: C204 | D30: UI UX Design | E30: B1 | F30: Priya | G30: Mobile | H30: 7779 | I30: DISC10 | J30: 0.1 | K30: 9000 | L30: 45298
A31: S1029 | B31: Rohit Verma | C31: C203 | D31: Full Stack Dev | E31: B2 | F31: Priya | G31: Mobile | H31: 18538 | I31: DISC10 | J31: 0.1 | K31: 17000 | L31: 45335
A32: S1030 | B32: Rohit Singh | C32: C201 | D32: Data Analytics | E32: B1 | F32: Priya | G32: Tablet | H32: 13389 | I32: DISC10 | J32: 0.1 | K32: 14000 | L32: 45307
A33: S1031 | B33: Sneha Patil | C33: C204 | D33: UI UX Design | E33: B1 | F33: Priya | G33: Web | H33: 8140 | K33: 9000 | L33: 45307
A34: S1032 | B34: Meera Shah | C34: C204 | D34: UI UX Design | E34: B3 | F34: Saurabh | G34: Web | H34: 9671 | I34: DISC15 | K34: 9000 | L34: 45345
A35: S1033 | B35: Aarav Shah | C35: C202 | D35: Data Science | E35: B1 | F35: Priya | G35: Mobile | H35: 12971 | I35: DISC20 | J35: 0.2 | K35: 13000 | L35: 45347
A36: S1034 | B36: Rahul Kulkarni | C36: C202 | D36: Data Science | E36: B2 | F36: Saurabh | G36: Mobile | H36: 12086 | K36: 13000 | L36: 45310
A37: S1035 | B37: Rahul Desai | C37: C204 | D37: UI UX Design | E37: B1 | F37: Saurabh | G37: Mobile | H37: 7891 | I37: DISC10 | J37: 0.1 | K37: 9000 | L37: 45329
A38: S1036 | B38: Anjali Gupta | C38: C201 | D38: Data Analytics | E38: B3 | F38: Priya | G38: Web | H38: 12205 | I38: DISC15 | K38: 14000 | L38: 45322
A39: S1037 | B39: Manish Nair | C39: C202 | D39: Data Science | E39: B1 | F39: Amit | G39: Web | H39: 14487 | I39: DISC20 | J39: 0.2 | K39: 13000 | L39: 45296
A40: S1038 | B40: Kavita Shah | C40: C202 | D40: Data Science | E40: B2 | F40: Saurabh | G40: Tablet | H40: 12008 | I40: DISC15 | K40: 13000 | L40: 45330
...

Sheet Q1
A1: CourseID | B1: CourseName
A2: C201 | B2: Data Analytics
A3: C203 | B3: Full Stack Dev
A4: C202 | B4: Data Science
A5: C204 | B5: UI UX Design

Sheet Q2
A1: Platform | B1: Total No of Enrollment
A2: Mobile | B2: =COUNTIF(Dataset!$A$1:$L$1001,'Q2'!A2) -> 321

Sheet Q3
A1: Course | B1: Total Payment Amount
A2: Data Analytics | B2: =SUMIF(Dataset!$D$1:$D$1001,'Q3'!A2,Dataset!$H$1:$H$1001) -> 3507731

Sheet Q4
A1: Student_id | B1: Mentor_name
A2: S1000 | B2: =VLOOKUP(A2,Dataset!$A$1:$L$1001,6,0) -> Priya
A3: s1007 | B3: =VLOOKUP(A3,Dataset!$A$1:$L$1001,6,0) -> Saurabh

Sheet Q5
A1: StudentID | B1: StudentName | C1: CourseID | D1: CourseName | E1: BatchID | F1: MentorName | G1: Platform | H1: PaymentAmount | I1: DiscountCode | J1: DiscountPercent | K1: TargetRevenue | L1: PaymentDate | M1: Performance Status | N1: Percentage of Record
A2: S1000 | B2: Rohit Shah | C2: C201 | D2: Data Analytics | E2: B3 | F2: Priya | G2: Web | H2: 12914 | I2: DISC20 | J2: 0.2 | K2: 14000 | L2: 45339 | M2: =IF(H2>=K2,"Target Achieved","Below Target") -> Below Target | N2: =COUNTIF($M$2:$M$1001,"Target Achieved")/COUNTA($M$2:$M$1001)*100 -> 51.6
A3: S1001 | B3: Riya Singh | C3: C201 | D3: Data Analytics | E3: B3 | F3: Priya | G3: Web | H3: 12122 | I3: DISC10 | J3: 0.1 | K3: 14000 | L3: 45305 | M3: =IF(H3>=K3,"Target Achieved","Below Target") -> Below Target
A4: S1002 | B4: Sneha Gupta | C4: C201 | D4: Data Analytics | E4: B3 | F4: Saurabh | G4: Tablet | H4: 14661 | I4: DISC15 | K4: 14000 | L4: 45318 | M4: =IF(H4>=K4,"Target Achieved","Below Target") -> Target Achieved
A5: S1003 | B5: Sneha Iyer | C5: C203 | D5: Full Stack Dev | E5: B1 | F5: Saurabh | G5: Tablet | H5: 16731 | I5: DISC30 | J5: 0.3 | K5: 17000 | L5: 45309 | M5: =IF(H5>=K5,"Target Achieved","Below Target") -> Below Target
A6: S1004 | B6: Karan Patil | C6: C203 | D6: Full Stack Dev | E6: B1 | F6: Saurabh | G6: Mobile | H6: 15396 | I6: DISC30 | J6: 0.3 | K6: 17000 | L6: 45346 | M6: =IF(H6>=K6,"Target Achieved","Below Target") -> Below Target
A7: S1005 | B7: Pooja Joshi | C7: C203 | D7: Full Stack Dev | E7: B1 | F7: Amit | G7: Mobile | H7: 17196 | I7: DISC10 | J7: 0.1 | K7: 17000 | L7: 45351 | M7: =IF(H7>=K7,"Target Achieved","Below Target") -> Target Achieved
A8: S1006 | B8: Rahul Shah | C8: C203 | D8: Full Stack Dev | E8: B3 | F8: Amit | G8: Mobile | H8: 17364 | I8: DISC20 | J8: 0.2 | K8: 17000 | L8: 45337 | M8: =IF(H8>=K8,"Target Achieved","Below Target") -> Target Achieved
A9: S1007 | B9: Riya Kulkarni | C9: C202 | D9: Data Science | E9: B2 | F9: Saurabh | G9: Web | H9: 14549 | I9: DISC10 | J9: 0.1 | K9: 13000 | L9: 45316 | M9: =IF(H9>=K9,"Target Achieved","Below Target") -> Target Achieved
A10: S1008 | B10: Aditya Iyer | C10: C203 | D10: Full Stack Dev | E10: B1 | F10: Priya | G10: Mobile | H10: 15858 | I10: DISC30 | J10: 0.3 | K10: 17000 | L10: 45336 | M10: =IF(H10>=K10,"Target Achieved","Below Target") -> Below Target
A11: S1009 | B11: Kunal Singh | C11: C201 | D11: Data Analytics | E11: B3 | F11: Amit | G11: Web | H11: 14187 | I11: DISC20 | J11: 0.2 | K11: 14000 | L11: 45302 | M11: =IF(H11>=K11,"Target Achieved","Below Target") -> Target Achieved
A12: S1010 | B12: Neha Verma | C12: C203 | D12: Full Stack Dev | E12: B3 | F12: Amit | G12: Tablet | H12: 15899 | I12: DISC30 | J12: 0.3 | K12: 17000 | L12: 45345 | M12: =IF(H12>=K12,"Target Achieved","Below Target") -> Below Target
A13: S1011 | B13: Dev Patel | C13: C201 | D13: Data Analytics | E13: B1 | F13: Saurabh | G13: Mobile | H13: 13643 | I13: DISC30 | J13: 0.3 | K13: 14000 | L13: 45296 | M13: =IF(H13>=K13,"Target Achieved","Below Target") -> Below Target
A14: S1012 | B14: Sneha Joshi | C14: C203 | D14: Full Stack Dev | E14: B1 | F14: Amit | G14: Mobile | H14: 16620 | K14: 17000 | L14: 45301 | M14: =IF(H14>=K14,"Target Achieved","Below Target") -> Below Target
A15: S1013 | B15: Aditya Mehta | C15: C202 | D15: Data Science | E15: B3 | F15: Amit | G15: Tablet | H15: 12076 | I15: DISC15 | K15: 13000 | L15: 45319 | M15: =IF(H15>=K15,"Target Achieved","Below Target") -> Below Target
A16: S1014 | B16: Kunal Joshi | C16: C204 | D16: UI UX Design | E16: B2 | F16: Saurabh | G16: Web | H16: 9087 | K16: 9000 | L16: 45297 | M16: =IF(H16>=K16,"Target Achieved","Below Target") -> Target Achieved
A17: S1015 | B17: Dev Kulkarni | C17: C201 | D17: Data Analytics | E17: B1 | F17: Amit | G17: Web | H17: 15244 | K17: 14000 | L17: 45330 | M17: =IF(H17>=K17,"Target Achieved","Below Target") -> Target Achieved
A18: S1016 | B18: Riya Verma | C18: C204 | D18: UI UX Design | E18: B3 | F18: Priya | G18: Tablet | H18: 8029 | I18: DISC15 | K18: 9000 | L18: 45347 | M18: =IF(H18>=K18,"Target Achieved","Below Target") -> Below Target
A19: S1017 | B19: Aarav Singh | C19: C201 | D19: Data Analytics | E19: B3 | F19: Amit | G19: Mobile | H19: 15148 | I19: DISC30 | J19: 0.3 | K19: 14000 | L19: 45299 | M19: =IF(H19>=K19,"Target Achieved","Below Target") -> Target Achieved
A20: S1018 | B20: Aditya Verma | C20: C202 | D20: Data Science | E20: B2 | F20: Saurabh | G20: Tablet | H20: 14587 | I20: DISC30 | J20: 0.3 | K20: 13000 | L20: 45324 | M20: =IF(H20>=K20,"Target Achieved","Below Target") -> Target Achieved
A21: S1019 | B21: Dev Mehta | C21: C201 | D21: Data Analytics | E21: B3 | F21: Priya | G21: Tablet | H21: 14079 | I21: DISC15 | K21: 14000 | L21: 45304 | M21: =IF(H21>=K21,"Target Achieved","Below Target") -> Target Achieved
A22: S1020 | B22: Karan Jain | C22: C202 | D22: Data Science | E22: B3 | F22: Amit | G22: Web | H22: 13453 | I22: DISC30 | J22: 0.3 | K22: 13000 | L22: 45323 | M22: =IF(H22>=K22,"Target Achieved","Below Target") -> Target Achieved
A23: S1021 | B23: Aarav Shah | C23: C203 | D23: Full Stack Dev | E23: B2 | F23: Saurabh | G23: Web | H23: 15986 | I23: DISC15 | K23: 17000 | L23: 45352 | M23: =IF(H23>=K23,"Target Achieved","Below Target") -> Below Target
A24: S1022 | B24: Riya Shah | C24: C204 | D24: UI UX Design | E24: B1 | F24: Amit | G24: Web | H24: 7525 | K24: 9000 | L24: 45352 | M24: =IF(H24>=K24,"Target Achieved","Below Target") -> Below Target
A25: S1023 | B25: Manish Mehta | C25: C203 | D25: Full Stack Dev | E25: B3 | F25: Amit | G25: Mobile | H25: 18950 | I25: DISC20 | J25: 0.2 | K25: 17000 | L25: 45351 | M25: =IF(H25>=K25,"Target Achieved","Below Target") -> Target Achieved
A26: S1024 | B26: Manish Patel | C26: C202 | D26: Data Science | E26: B3 | F26: Priya | G26: Mobile | H26: 13751 | I26: DISC30 | J26: 0.3 | K26: 13000 | L26: 45320 | M26: =IF(H26>=K26,"Target Achieved","Below Target") -> Target Achieved
A27: S1025 | B27: Kunal Gupta | C27: C204 | D27: UI UX Design | E27: B1 | F27: Saurabh | G27: Web | H27: 7262 | I27: DISC30 | J27: 0.3 | K27: 9000 | L27: 45293 | M27: =IF(H27>=K27,"Target Achieved","Below Target") -> Below Target
A28: S1026 | B28: Kavita Gupta | C28: C202 | D28: Data Science | E28: B3 | F28: Saurabh | G28: Web | H28: 11290 | I28: DISC10 | J28: 0.1 | K28: 13000 | L28: 45306 | M28: =IF(H28>=K28,"Target Achieved","Below Target") -> Below Target
A29: S1027 | B29: Riya Kulkarni | C29: C203 | D29: Full Stack Dev | E29: B1 | F29: Amit | G29: Web | H29: 16140 | K29: 17000 | L29: 45305 | M29: =IF(H29>=K29,"Target Achieved","Below Target") -> Below Target
A30: S1028 | B30: Manish Mehta | C30: C204 | D30: UI UX Design | E30: B1 | F30: Priya | G30: Mobile | H30: 7779 | I30: DISC10 | J30: 0.1 | K30: 9000 | L30: 45298 | M30: =IF(H30>=K30,"Target Achieved","Below Target") -> Below Target
A31: S1029 | B31: Rohit Verma | C31: C203 | D31: Full Stack Dev | E31: B2 | F31: Priya | G31: Mobile | H31: 18538 | I31: DISC10 | J31: 0.1 | K31: 17000 | L31: 45335 | M31: =IF(H31>=K31,"Target Achieved","Below Target") -> Target Achieved
A32: S1030 | B32: Rohit Singh | C32: C201 | D32: Data Analytics | E32: B1 | F32: Priya | G32: Tablet | H32: 13389 | I32: DISC10 | J32: 0.1 | K32: 14000 | L32: 45307 | M32: =IF(H32>=K32,"Target Achieved","Below Target") -> Below Target
A33: S1031 | B33: Sneha Patil | C33: C204 | D33: UI UX Design | E33: B1 | F33: Priya | G33: Web | H33: 8140 | K33: 9000 | L33: 45307 | M33: =IF(H33>=K33,"Target Achieved","Below Target") -> Below Target
A34: S1032 | B34: Meera Shah | C34: C204 | D34: UI UX Design | E34: B3 | F34: Saurabh | G34: Web | H34: 9671 | I34: DISC15 | K34: 9000 | L34: 45345 | M34: =IF(H34>=K34,"Target Achieved","Below Target") -> Target Achieved
A35: S1033 | B35: Aarav Shah | C35: C202 | D35: Data Science | E35: B1 | F35: Priya | G35: Mobile | H35: 12971 | I35: DISC20 | J35: 0.2 | K35: 13000 | L35: 45347 | M35: =IF(H35>=K35,"Target Achieved","Below Target") -> Below Target
A36: S1034 | B36: Rahul Kulkarni | C36: C202 | D36: Data Science | E36: B2 | F36: Saurabh | G36: Mobile | H36: 12086 | K36: 13000 | L36: 45310 | M36: =IF(H36>=K36,"Target Achieved","Below Target") -> Below Target
A37: S1035 | B37: Rahul Desai | C37: C204 | D37: UI UX Design | E37: B1 | F37: Saurabh | G37: Mobile | H37: 7891 | I37: DISC10 | J37: 0.1 | K37: 9000 | L37: 45329 | M37: =IF(H37>=K37,"Target Achieved","Below Target") -> Below Target
A38: S1036 | B38: Anjali Gupta | C38: C201 | D38: Data Analytics | E38: B3 | F38: Priya | G38: Web | H38: 12205 | I38: DISC15 | K38: 14000 | L38: 45322 | M38: =IF(H38>=K38,"Target Achieved","Below Target") -> Below Target
A39: S1037 | B39: Manish Nair | C39: C202 | D39: Data Science | E39: B1 | F39: Amit | G39: Web | H39: 14487 | I39: DISC20 | J39: 0.2 | K39: 13000 | L39: 45296 | M39: =IF(H39>=K39,"Target Achieved","Below Target") -> Target Achieved
A40: S1038 | B40: Kavita Shah | C40: C202 | D40: Data Science | E40: B2 | F40: Saurabh | G40: Tablet | H40: 12008 | I40: DISC15 | K40: 13000 | L40: 45330 | M40: =IF(H40>=K40,"Target Achieved","Below Target") -> Below Target
...

Sheet Q6
A1: StudentID | B1: StudentName | C1: CourseID | D1: CourseName | E1: BatchID | F1: MentorName | G1: Platform | H1: PaymentAmount | I1: DiscountCode | J1: DiscountPercent | K1: TargetRevenue | L1: PaymentDate | M1: New_DiscountPercent
A2: S1000 | B2: Rohit Shah | C2: C201 | D2: Data Analytics | E2: B3 | F2: Priya | G2: Web | H2: 12914 | I2: DISC20 | J2: 0.2 | K2: 14000 | L2: 45339 | M2: =IF(OR(I2="",ISNA(MATCH(I2,{"DISC10","DISC15","DISC20","DISC30"},0))),0,J2) -> 0.2
A3: S1001 | B3: Riya Singh | C3: C201 | D3: Data Analytics | E3: B3 | F3: Priya | G3: Web | H3: 12122 | I3: DISC10 | J3: 0.1 | K3: 14000 | L3: 45305 | M3: =IF(OR(I3="",ISNA(MATCH(I3,{"DISC10","DISC15","DISC20","DISC30"},0))),0,J3) -> 0.1
A4: S1002 | B4: Sneha Gupta | C4: C201 | D4: Data Analytics | E4: B3 | F4: Saurabh | G4: Tablet | H4: 14661 | I4: DISC15 | K4: 14000 | L4: 45318 | M4: =IF(OR(I4="",ISNA(MATCH(I4,{"DISC10","DISC15","DISC20","DISC30"},0))),0,J4) -> 0
A5: S1003 | B5: Sneha Iyer | C5: C203 | D5: Full Stack Dev | E5: B1 | F5: Saurabh | G5: Tablet | H5: 16731 | I5: DISC30 | J5: 0.3 | K5: 17000 | L5: 45309 | M5: =IF(OR(I5="",ISNA(MATCH(I5,{"DISC10","DISC15","DISC20","DISC30"},0))),0,J5) -> 0.3
A6: S1004 | B6: Karan Patil | C6: C203 | D6: Full Stack Dev | E6: B1 | F6: Saurabh | G6: Mobile | H6: 15396 | I6: DISC30 | J6: 0.3 | K6: 17000 | L6: 45346 | M6: =IF(OR(I6="",ISNA(MATCH(I6,{"DISC10","DISC15","DISC20","DISC30"},0))),0,J6) -> 0.3
A7: S1005 | B7: Pooja Joshi | C7: C203 | D7: Full Stack Dev | E7: B1 | F7: Amit | G7: Mobile | H7: 17196 | I7: DISC10 | J7: 0.1 | K7: 17000 | L7: 45351 | M7: =IF(OR(I7="",ISNA(MATCH(I7,{"DISC10","DISC15","DISC20","DISC30"},0))),0,J7) -> 0.1
A8: S1006 | B8: Rahul Shah | C8: C203 | D8: Full Stack Dev | E8: B3 | F8: Amit | G8: Mobile | H8: 17364 | I8: DISC20 | J8: 0.2 | K8: 17000 | L8: 45337 | M8: =IF(OR(I8="",ISNA(MATCH(I8,{"DISC10","DISC15","DISC20","DISC30"},0))),0,J8) -> 0.2
A9: S1007 | B9: Riya Kulkarni | C9: C202 | D9: Data Science | E9: B2 | F9: Saurabh | G9: Web | H9: 14549 | I9: DISC10 | J9: 0.1 | K9: 13000 | L9: 45316 | M9: =IF(OR(I9="",ISNA(MATCH(I9,{"DISC10","DISC15","DISC20","DISC30"},0))),0,J9) -> 0.1
A10: S1008 | B10: Aditya Iyer | C10: C203 | D10: Full Stack Dev | E10: B1 | F10: Priya | G10: Mobile | H10: 15858 | I10: DISC30 | J10: 0.3 | K10: 17000 | L10: 45336 | M10: =IF(OR(I10="",ISNA(MATCH(I10,{"DISC10","DISC15","DISC20","DISC30"},0))),0,J10) -> 0.3
A11: S1009 | B11: Kunal Singh | C11: C201 | D11: Data Analytics | E11: B3 | F11: Amit | G11: Web | H11: 14187 | I11: DISC20 | J11: 0.2 | K11: 14000 | L11: 45302 | M11: =IF(OR(I11="",ISNA(MATCH(I11,{"DISC10","DISC15","DISC20","DISC30"},0))),0,J11) -> 0.2
A12: S1010 | B12: Neha Verma | C12: C203 | D12: Full Stack Dev | E12: B3 | F12: Amit | G12: Tablet | H12: 15899 | I12: DISC30 | J12: 0.3 | K12: 17000 | L12: 45345 | M12: =IF(OR(I12="",ISNA(MATCH(I12,{"DISC10","DISC15","DISC20","DISC30"},0))),0,J12) -> 0.3
A13: S1011 | B13: Dev Patel | C13: C201 | D13: Data Analytics | E13: B1 | F13: Saurabh | G13: Mobile | H13: 13643 | I13: DISC30 | J13: 0.3 | K13: 14000 | L13: 45296 | M13: =IF(OR(I13="",ISNA(MATCH(I13,{"DISC10","DISC15","DISC20","DISC30"},0))),0,J13) -> 0.3
A14: S1012 | B14: Sneha Joshi | C14: C203 | D14: Full Stack Dev | E14: B1 | F14: Amit | G14: Mobile | H14: 16620 | K14: 17000 | L14: 45301 | M14: =IF(OR(I14="",ISNA(MATCH(I14,{"DISC10","DISC15","DISC20","DISC30"},0))),0,J14) -> 0
A15: S1013 | B15: Aditya Mehta | C15: C202 | D15: Data Science | E15: B3 | F15: Amit | G15: Tablet | H15: 12076 | I15: DISC15 | K15: 13000 | L15: 45319 | M15: =IF(OR(I15="",ISNA(MATCH(I15,{"DISC10","DISC15","DISC20","DISC30"},0))),0,J15) -> 0
A16: S1014 | B16: Kunal Joshi | C16: C204 | D16: UI UX Design | E16: B2 | F16: Saurabh | G16: Web | H16: 9087 | K16: 9000 | L16: 45297 | M16: =IF(OR(I16="",ISNA(MATCH(I16,{"DISC10","DISC15","DISC20","DISC30"},0))),0,J16) -> 0
A17: S1015 | B17: Dev Kulkarni | C17: C201 | D17: Data Analytics | E17: B1 | F17: Amit | G17: Web | H17: 15244 | K17: 14000 | L17: 45330 | M17: =IF(OR(I17="",ISNA(MATCH(I17,{"DISC10","DISC15","DISC20","DISC30"},0))),0,J17) -> 0
A18: S1016 | B18: Riya Verma | C18: C204 | D18: UI UX Design | E18: B3 | F18: Priya | G18: Tablet | H18: 8029 | I18: DISC15 | K18: 9000 | L18: 45347 | M18: =IF(OR(I18="",ISNA(MATCH(I18,{"DISC10","DISC15","DISC20","DISC30"},0))),0,J18) -> 0
A19: S1017 | B19: Aarav Singh | C19: C201 | D19: Data Analytics | E19: B3 | F19: Amit | G19: Mobile | H19: 15148 | I19: DISC30 | J19: 0.3 | K19: 14000 | L19: 45299 | M19: =IF(OR(I19="",ISNA(MATCH(I19,{"DISC10","DISC15","DISC20","DISC30"},0))),0,J19) -> 0.3
A20: S1018 | B20: Aditya Verma | C20: C202 | D20: Data Science | E20: B2 | F20: Saurabh | G20: Tablet | H20: 14587 | I20: DISC30 | J20: 0.3 | K20: 13000 | L20: 45324 | M20: =IF(OR(I20="",ISNA(MATCH(I20,{"DISC10","DISC15","DISC20","DISC30"},0))),0,J20) -> 0.3
A21: S1019 | B21: Dev Mehta | C21: C201 | D21: Data Analytics | E21: B3 | F21: Priya | G21: Tablet | H21: 14079 | I21: DISC15 | K21: 14000 | L21: 45304 | M21: =IF(OR(I21="",ISNA(MATCH(I21,{"DISC10","DISC15","DISC20","DISC30"},0))),0,J21) -> 0
A22: S1020 | B22: Karan Jain | C22: C202 | D22: Data Science | E22: B3 | F22: Amit | G22: Web | H22: 13453 | I22: DISC30 | J22: 0.3 | K22: 13000 | L22: 45323 | M22: =IF(OR(I22="",ISNA(MATCH(I22,{"DISC10","DISC15","DISC20","DISC30"},0))),0,J22) -> 0.3
A23: S1021 | B23: Aarav Shah | C23: C203 | D23: Full Stack Dev | E23: B2 | F23: Saurabh | G23: Web | H23: 15986 | I23: DISC15 | K23: 17000 | L23: 45352 | M23: =IF(OR(I23="",ISNA(MATCH(I23,{"DISC10","DISC15","DISC20","DISC30"},0))),0,J23) -> 0
A24: S1022 | B24: Riya Shah | C24: C204 | D24: UI UX Design | E24: B1 | F24: Amit | G24: Web | H24: 7525 | K24: 9000 | L24: 45352 | M24: =IF(OR(I24="",ISNA(MATCH(I24,{"DISC10","DISC15","DISC20","DISC30"},0))),0,J24) -> 0
A25: S1023 | B25: Manish Mehta | C25: C203 | D25: Full Stack Dev | E25: B3 | F25: Amit | G25: Mobile | H25: 18950 | I25: DISC20 | J25: 0.2 | K25: 17000 | L25: 45351 | M25: =IF(OR(I25="",ISNA(MATCH(I25,{"DISC10","DISC15","DISC20","DISC30"},0))),0,J25) -> 0.2
A26: S1024 | B26: Manish Patel | C26: C202 | D26: Data Science | E26: B3 | F26: Priya | G26: Mobile | H26: 13751 | I26: DISC30 | J26: 0.3 | K26: 13000 | L26: 45320 | M26: =IF(OR(I26="",ISNA(MATCH(I26,{"DISC10","DISC15","DISC20","DISC30"},0))),0,J26) -> 0.3
A27: S1025 | B27: Kunal Gupta | C27: C204 | D27: UI UX Design | E27: B1 | F27: Saurabh | G27: Web | H27: 7262 | I27: DISC30 | J27: 0.3 | K27: 9000 | L27: 45293 | M27: =IF(OR(I27="",ISNA(MATCH(I27,{"DISC10","DISC15","DISC20","DISC30"},0))),0,J27) -> 0.3
A28: S1026 | B28: Kavita Gupta | C28: C202 | D28: Data Science | E28: B3 | F28: Saurabh | G28: Web | H28: 11290 | I28: DISC10 | J28: 0.1 | K28: 13000 | L28: 45306 | M28: =IF(OR(I28="",ISNA(MATCH(I28,{"DISC10","DISC15","DISC20","DISC30"},0))),0,J28) -> 0.1
A29: S1027 | B29: Riya Kulkarni | C29: C203 | D29: Full Stack Dev | E29: B1 | F29: Amit | G29: Web | H29: 16140 | K29: 17000 | L29: 45305 | M29: =IF(OR(I29="",ISNA(MATCH(I29,{"DISC10","DISC15","DISC20","DISC30"},0))),0,J29) -> 0
A30: S1028 | B30: Manish Mehta | C30: C204 | D30: UI UX Design | E30: B1 | F30: Priya | G30: Mobile | H30: 7779 | I30: DISC10 | J30: 0.1 | K30: 9000 | L30: 45298 | M30: =IF(OR(I30="",ISNA(MATCH(I30,{"DISC10","DISC15","DISC20","DISC30"},0))),0,J30) -> 0.1
A31: S1029 | B31: Rohit Verma | C31: C203 | D31: Full Stack Dev | E31: B2 | F31: Priya | G31: Mobile | H31: 18538 | I31: DISC10 | J31: 0.1 | K31: 17000 | L31: 45335 | M31: =IF(OR(I31="",ISNA(MATCH(I31,{"DISC10","DISC15","DISC20","DISC30"},0))),0,J31) -> 0.1
A32: S1030 | B32: Rohit Singh | C32: C201 | D32: Data Analytics | E32: B1 | F32: Priya | G32: Tablet | H32: 13389 | I32: DISC10 | J32: 0.1 | K32: 14000 | L32: 45307 | M32: =IF(OR(I32="",ISNA(MATCH(I32,{"DISC10","DISC15","DISC20","DISC30"},0))),0,J32) -> 0.1
A33: S1031 | B33: Sneha Patil | C33: C204 | D33: UI UX Design | E33: B1 | F33: Priya | G33: Web | H33: 8140 | K33: 9000 | L33: 45307 | M33: =IF(OR(I33="",ISNA(MATCH(I33,{"DISC10","DISC15","DISC20","DISC30"},0))),0,J33) -> 0
A34: S1032 | B34: Meera Shah | C34: C204 | D34: UI UX Design | E34: B3 | F34: Saurabh | G34: Web | H34: 9671 | I34: DISC15 | K34: 9000 | L34: 45345 | M34: =IF(OR(I34="",ISNA(MATCH(I34,{"DISC10","DISC15","DISC20","DISC30"},0))),0,J34) -> 0
A35: S1033 | B35: Aarav Shah | C35: C202 | D35: Data Science | E35: B1 | F35: Priya | G35: Mobile | H35: 12971 | I35: DISC20 | J35: 0.2 | K35: 13000 | L35: 45347 | M35: =IF(OR(I35="",ISNA(MATCH(I35,{"DISC10","DISC15","DISC20","DISC30"},0))),0,J35) -> 0.2
A36: S1034 | B36: Rahul Kulkarni | C36: C202 | D36: Data Science | E36: B2 | F36: Saurabh | G36: Mobile | H36: 12086 | K36: 13000 | L36: 45310 | M36: =IF(OR(I36="",ISNA(MATCH(I36,{"DISC10","DISC15","DISC20","DISC30"},0))),0,J36) -> 0
A37: S1035 | B37: Rahul Desai | C37: C204 | D37: UI UX Design | E37: B1 | F37: Saurabh | G37: Mobile | H37: 7891 | I37: DISC10 | J37: 0.1 | K37: 9000 | L37: 45329 | M37: =IF(OR(I37="",ISNA(MATCH(I37,{"DISC10","DISC15","DISC20","DISC30"},0))),0,J37) -> 0.1
A38: S1036 | B38: Anjali Gupta | C38: C201 | D38: Data Analytics | E38: B3 | F38: Priya | G38: Web | H38: 12205 | I38: DISC15 | K38: 14000 | L38: 45322 | M38: =IF(OR(I38="",ISNA(MATCH(I38,{"DISC10","DISC15","DISC20","DISC30"},0))),0,J38) -> 0
A39: S1037 | B39: Manish Nair | C39: C202 | D39: Data Science | E39: B1 | F39: Amit | G39: Web | H39: 14487 | I39: DISC20 | J39: 0.2 | K39: 13000 | L39: 45296 | M39: =IF(OR(I39="",ISNA(MATCH(I39,{"DISC10","DISC15","DISC20","DISC30"},0))),0,J39) -> 0.2
A40: S1038 | B40: Kavita Shah | C40: C202 | D40: Data Science | E40: B2 | F40: Saurabh | G40: Tablet | H40: 12008 | I40: DISC15 | K40: 13000 | L40: 45330 | M40: =IF(OR(I40="",ISNA(MATCH(I40,{"DISC10","DISC15","DISC20","DISC30"},0))),0,J40) -> 0
...

Sheet Q7
A1: STUDENT_NAME | B1: PLATFORM
A2: Rohit Shah | B2: =INDEX(Dataset!$G$1:$G$1001,MATCH('Q7'!A2,Dataset!$B$1:$B$1001,0)) -> Web
A3: Riya Verma | B3: =INDEX(Dataset!$G$1:$G$1001,MATCH('Q7'!A3,Dataset!$B$1:$B$1001,0)) -> Tablet

Sheet Q8
A1: StudentID | B1: StudentName | C1: CourseID | D1: CourseName | E1: BatchID | F1: MentorName | G1: Platform | H1: PaymentAmount | I1: DiscountCode | J1: DiscountPercent | K1: TargetRevenue | L1: PaymentDate | M1: Total Net Revenue(AfterDiscount)
A2: S1000 | B2: Rohit Shah | C2: C201 | D2: Data Analytics | E2: B3 | F2: Priya | G2: Web | H2: 12914 | I2: DISC20 | J2: 0.2 | K2: 14000 | L2: 45339 | M2: {=SUM($H$2:$H$1001*(1-$J$2:$J$1001))} -> 11745723
A3: S1001 | B3: Riya Singh | C3: C201 | D3: Data Analytics | E3: B3 | F3: Priya | G3: Web | H3: 12122 | I3: DISC10 | J3: 0.1 | K3: 14000 | L3: 45305
A4: S1002 | B4: Sneha Gupta | C4: C201 | D4: Data Analytics | E4: B3 | F4: Saurabh | G4: Tablet | H4: 14661 | I4: DISC15 | K4: 14000 | L4: 45318
A5: S1003 | B5: Sneha Iyer | C5: C203 | D5: Full Stack Dev | E5: B1 | F5: Saurabh | G5: Tablet | H5: 16731 | I5: DISC30 | J5: 0.3 | K5: 17000 | L5: 45309 | M5: Total Revenue(Before Discount)
A6: S1004 | B6: Karan Patil | C6: C203 | D6: Full Stack Dev | E6: B1 | F6: Saurabh | G6: Mobile | H6: 15396 | I6: DISC30 | J6: 0.3 | K6: 17000 | L6: 45346 | M6: =SUM($H$2:$H$1001) -> 13395293
A7: S1005 | B7: Pooja Joshi | C7: C203 | D7: Full Stack Dev | E7: B1 | F7: Amit | G7: Mobile | H7: 17196 | I7: DISC10 | J7: 0.1 | K7: 17000 | L7: 45351
A8: S1006 | B8: Rahul Shah | C8: C203 | D8: Full Stack Dev | E8: B3 | F8: Amit | G8: Mobile | H8: 17364 | I8: DISC20 | J8: 0.2 | K8: 17000 | L8: 45337 | M8: Total Discount
A9: S1007 | B9: Riya Kulkarni | C9: C202 | D9: Data Science | E9: B2 | F9: Saurabh | G9: Web | H9: 14549 | I9: DISC10 | J9: 0.1 | K9: 13000 | L9: 45316 | M9: =M6-M2 -> 1649570.2
A10: S1008 | B10: Aditya Iyer | C10: C203 | D10: Full Stack Dev | E10: B1 | F10: Priya | G10: Mobile | H10: 15858 | I10: DISC30 | J10: 0.3 | K10: 17000 | L10: 45336
A11: S1009 | B11: Kunal Singh | C11: C201 | D11: Data Analytics | E11: B3 | F11: Amit | G11: Web | H11: 14187 | I11: DISC20 | J11: 0.2 | K11: 14000 | L11: 45302
A12: S1010 | B12: Neha Verma | C12: C203 | D12: Full Stack Dev | E12: B3 | F12: Amit | G12: Tablet | H12: 15899 | I12: DISC30 | J12: 0.3 | K12: 17000 | L12: 45345
A13: S1011 | B13: Dev Patel | C13: C201 | D13: Data Analytics | E13: B1 | F13: Saurabh | G13: Mobile | H13: 13643 | I13: DISC30 | J13: 0.3 | K13: 14000 | L13: 45296
A14: S1012 | B14: Sneha Joshi | C14: C203 | D14: Full Stack Dev | E14: B1 | F14: Amit | G14: Mobile | H14: 16620 | K14: 17000 | L14: 45301
A15: S1013 | B15: Aditya Mehta | C15: C202 | D15: Data Science | E15: B3 | F15: Amit | G15: Tablet | H15: 12076 | I15: DISC15 | K15: 13000 | L15: 45319
A16: S1014 | B16: Kunal Joshi | C16: C204 | D16: UI UX Design | E16: B2 | F16: Saurabh | G16: Web | H16: 9087 | K16: 9000 | L16: 45297
A17: S1015 | B17: Dev Kulkarni | C17: C201 | D17: Data Analytics | E17: B1 | F17: Amit | G17: Web | H17: 15244 | K17: 14000 | L17: 45330
A18: S1016 | B18: Riya Verma | C18: C204 | D18: UI UX Design | E18: B3 | F18: Priya | G18: Tablet | H18: 8029 | I18: DISC15 | K18: 9000 | L18: 45347
A19: S1017 | B19: Aarav Singh | C19: C201 | D19: Data Analytics | E19: B3 | F19: Amit | G19: Mobile | H19: 15148 | I19: DISC30 | J19: 0.3 | K19: 14000 | L19: 45299
A20: S1018 | B20: Aditya Verma | C20: C202 | D20: Data Science | E20: B2 | F20: Saurabh | G20: Tablet | H20: 14587 | I20: DISC30 | J20: 0.3 | K20: 13000 | L20: 45324
A21: S1019 | B21: Dev Mehta | C21: C201 | D21: Data Analytics | E21: B3 | F21: Priya | G21: Tablet | H21: 14079 | I21: DISC15 | K21: 14000 | L21: 45304
A22: S1020 | B22: Karan Jain | C22: C202 | D22: Data Science | E22: B3 | F22: Amit | G22: Web | H22: 13453 | I22: DISC30 | J22: 0.3 | K22: 13000 | L22: 45323
A23: S1021 | B23: Aarav Shah | C23: C203 | D23: Full Stack Dev | E23: B2 | F23: Saurabh | G23: Web | H23: 15986 | I23: DISC15 | K23: 17000 | L23: 45352
A24: S1022 | B24: Riya Shah | C24: C204 | D24: UI UX Design | E24: B1 | F24: Amit | G24: Web | H24: 7525 | K24: 9000 | L24: 45352
A25: S1023 | B25: Manish Mehta | C25: C203 | D25: Full Stack Dev | E25: B3 | F25: Amit | G25: Mobile | H25: 18950 | I25: DISC20 | J25: 0.2 | K25: 17000 | L25: 45351
A26: S1024 | B26: Manish Patel | C26: C202 | D26: Data Science | E26: B3 | F26: Priya | G26: Mobile | H26: 13751 | I26: DISC30 | J26: 0.3 | K26: 13000 | L26: 45320
A27: S1025 | B27: Kunal Gupta | C27: C204 | D27: UI UX Design | E27: B1 | F27: Saurabh | G27: Web | H27: 7262 | I27: DISC30 | J27: 0.3 | K27: 9000 | L27: 45293
A28: S1026 | B28: Kavita Gupta | C28: C202 | D28: Data Science | E28: B3 | F28: Saurabh | G28: Web | H28: 11290 | I28: DISC10 | J28: 0.1 | K28: 13000 | L28: 45306
A29: S1027 | B29: Riya Kulkarni | C29: C203 | D29: Full Stack Dev | E29: B1 | F29: Amit | G29: Web | H29: 16140 | K29: 17000 | L29: 45305
A30: S1028 | B30: Manish Mehta | C30: C204 | D30: UI UX Design | E30: B1 | F30: Priya | G30: Mobile | H30: 7779 | I30: DISC10 | J30: 0.1 | K30: 9000 | L30: 45298
A31: S1029 | B31: Rohit Verma | C31: C203 | D31: Full Stack Dev | E31: B2 | F31: Priya | G31: Mobile | H31: 18538 | I31: DISC10 | J31: 0.1 | K31: 17000 | L31: 45335
A32: S1030 | B32: Rohit Singh | C32: C201 | D32: Data Analytics | E32: B1 | F32: Priya | G32: Tablet | H32: 13389 | I32: DISC10 | J32: 0.1 | K32: 14000 | L32: 45307
A33: S1031 | B33: Sneha Patil | C33: C204 | D33: UI UX Design | E33: B1 | F33: Priya | G33: Web | H33: 8140 | K33: 9000 | L33: 45307
A34: S1032 | B34: Meera Shah | C34: C204 | D34: UI UX Design | E34: B3 | F34: Saurabh | G34: Web | H34: 9671 | I34: DISC15 | K34: 9000 | L34: 45345
A35: S1033 | B35: Aarav Shah | C35: C202 | D35: Data Science | E35: B1 | F35: Priya | G35: Mobile | H35: 12971 | I35: DISC20 | J35: 0.2 | K35: 13000 | L35: 45347
A36: S1034 | B36: Rahul Kulkarni | C36: C202 | D36: Data Science | E36: B2 | F36: Saurabh | G36: Mobile | H36: 12086 | K36: 13000 | L36: 45310
A37: S1035 | B37: Rahul Desai | C37: C204 | D37: UI UX Design | E37: B1 | F37: Saurabh | G37: Mobile | H37: 7891 | I37: DISC10 | J37: 0.1 | K37: 9000 | L37: 45329
A38: S1036 | B38: Anjali Gupta | C38: C201 | D38: Data Analytics | E38: B3 | F38: Priya | G38: Web | H38: 12205 | I38: DISC15 | K38: 14000 | L38: 45322
A39: S1037 | B39: Manish Nair | C39: C202 | D39: Data Science | E39: B1 | F39: Amit | G39: Web | H39: 14487 | I39: DISC20 | J39: 0.2 | K39: 13000 | L39: 45296
A40: S1038 | B40: Kavita Shah | C40: C202 | D40: Data Science | E40: B2 | F40: Saurabh | G40: Tablet | H40: 12008 | I40: DISC15 | K40: 13000 | L40: 45330
...

Sheet Q9
A1: StudentID | B1: StudentName | C1: CourseID | D1: CourseName | E1: BatchID | F1: MentorName | G1: Platform | H1: PaymentAmount | I1: DiscountCode | J1: DiscountPercent | K1: TargetRevenue | L1: PaymentDate
A2: S1000 | B2: Rohit Shah | C2: C201 | D2: Data Analytics | E2: B3 | F2: Priya | G2: Web | H2: 12914 | I2: DISC20 | J2: 0.2 | K2: 14000 | L2: 45339
A3: S1001 | B3: Riya Singh | C3: C201 | D3: Data Analytics | E3: B3 | F3: Priya | G3: Web | H3: 12122 | I3: DISC10 | J3: 0.1 | K3: 14000 | L3: 45305 | O3: Counts no of Records = | Q3: =COUNTIFS($D$2:$D$1001,"Data Analytics",$G$2:$G$1001,"Web") -> 65
A4: S1002 | B4: Sneha Gupta | C4: C201 | D4: Data Analytics | E4: B3 | F4: Saurabh | G4: Tablet | H4: 14661 | I4: DISC15 | K4: 14000 | L4: 45318
A5: S1003 | B5: Sneha Iyer | C5: C203 | D5: Full Stack Dev | E5: B1 | F5: Saurabh | G5: Tablet | H5: 16731 | I5: DISC30 | J5: 0.3 | K5: 17000 | L5: 45309
A6: S1004 | B6: Karan Patil | C6: C203 | D6: Full Stack Dev | E6: B1 | F6: Saurabh | G6: Mobile | H6: 15396 | I6: DISC30 | J6: 0.3 | K6: 17000 | L6: 45346
A7: S1005 | B7: Pooja Joshi | C7: C203 | D7: Full Stack Dev | E7: B1 | F7: Amit | G7: Mobile | H7: 17196 | I7: DISC10 | J7: 0.1 | K7: 17000 | L7: 45351
A8: S1006 | B8: Rahul Shah | C8: C203 | D8: Full Stack Dev | E8: B3 | F8: Amit | G8: Mobile | H8: 17364 | I8: DISC20 | J8: 0.2 | K8: 17000 | L8: 45337
A9: S1007 | B9: Riya Kulkarni | C9: C202 | D9: Data Science | E9: B2 | F9: Saurabh | G9: Web | H9: 14549 | I9: DISC10 | J9: 0.1 | K9: 13000 | L9: 45316
A10: S1008 | B10: Aditya Iyer | C10: C203 | D10: Full Stack Dev | E10: B1 | F10: Priya | G10: Mobile | H10: 15858 | I10: DISC30 | J10: 0.3 | K10: 17000 | L10: 45336
A11: S1009 | B11: Kunal Singh | C11: C201 | D11: Data Analytics | E11: B3 | F11: Amit | G11: Web | H11: 14187 | I11: DISC20 | J11: 0.2 | K11: 14000 | L11: 45302
A12: S1010 | B12: Neha Verma | C12: C203 | D12: Full Stack Dev | E12: B3 | F12: Amit | G12: Tablet | H12: 15899 | I12: DISC30 | J12: 0.3 | K12: 17000 | L12: 45345
A13: S1011 | B13: Dev Patel | C13: C201 | D13: Data Analytics | E13: B1 | F13: Saurabh | G13: Mobile | H13: 13643 | I13: DISC30 | J13: 0.3 | K13: 14000 | L13: 45296
A14: S1012 | B14: Sneha Joshi | C14: C203 | D14: Full Stack Dev | E14: B1 | F14: Amit | G14: Mobile | H14: 16620 | K14: 17000 | L14: 45301
A15: S1013 | B15: Aditya Mehta | C15: C202 | D15: Data Science | E15: B3 | F15: Amit | G15: Tablet | H15: 12076 | I15: DISC15 | K15: 13000 | L15: 45319
A16: S1014 | B16: Kunal Joshi | C16: C204 | D16: UI UX Design | E16: B2 | F16: Saurabh | G16: Web | H16: 9087 | K16: 9000 | L16: 45297
A17: S1015 | B17: Dev Kulkarni | C17: C201 | D17: Data Analytics | E17: B1 | F17: Amit | G17: Web | H17: 15244 | K17: 14000 | L17: 45330
A18: S1016 | B18: Riya Verma | C18: C204 | D18: UI UX Design | E18: B3 | F18: Priya | G18: Tablet | H18: 8029 | I18: DISC15 | K18: 9000 | L18: 45347
A19: S1017 | B19: Aarav Singh | C19: C201 | D19: Data Analytics | E19: B3 | F19: Amit | G19: Mobile | H19: 15148 | I19: DISC30 | J19: 0.3 | K19: 14000 | L19: 45299
A20: S1018 | B20: Aditya Verma | C20: C202 | D20: Data Science | E20: B2 | F20: Saurabh | G20: Tablet | H20: 14587 | I20: DISC30 | J20: 0.3 | K20: 13000 | L20: 45324
A21: S1019 | B21: Dev Mehta | C21: C201 | D21: Data Analytics | E21: B3 | F21: Priya | G21: Tablet | H21: 14079 | I21: DISC15 | K21: 14000 | L21: 45304
A22: S1020 | B22: Karan Jain | C22: C202 | D22: Data Science | E22: B3 | F22: Amit | G22: Web | H22: 13453 | I22: DISC30 | J22: 0.3 | K22: 13000 | L22: 45323
A23: S1021 | B23: Aarav Shah | C23: C203 | D23: Full Stack Dev | E23: B2 | F23: Saurabh | G23: Web | H23: 15986 | I23: DISC15 | K23: 17000 | L23: 45352
A24: S1022 | B24: Riya Shah | C24: C204 | D24: UI UX Design | E24: B1 | F24: Amit | G24: Web | H24: 7525 | K24: 9000 | L24: 45352
A25: S1023 | B25: Manish Mehta | C25: C203 | D25: Full Stack Dev | E25: B3 | F25: Amit | G25: Mobile | H25: 18950 | I25: DISC20 | J25: 0.2 | K25: 17000 | L25: 45351
A26: S1024 | B26: Manish Patel | C26: C202 | D26: Data Science | E26: B3 | F26: Priya | G26: Mobile | H26: 13751 | I26: DISC30 | J26: 0.3 | K26: 13000 | L26: 45320
A27: S1025 | B27: Kunal Gupta | C27: C204 | D27: UI UX Design | E27: B1 | F27: Saurabh | G27: Web | H27: 7262 | I27: DISC30 | J27: 0.3 | K27: 9000 | L27: 45293
A28: S1026 | B28: Kavita Gupta | C28: C202 | D28: Data Science | E28: B3 | F28: Saurabh | G28: Web | H28: 11290 | I28: DISC10 | J28: 0.1 | K28: 13000 | L28: 45306
A29: S1027 | B29: Riya Kulkarni | C29: C203 | D29: Full Stack Dev | E29: B1 | F29: Amit | G29: Web | H29: 16140 | K29: 17000 | L29: 45305
A30: S1028 | B30: Manish Mehta | C30: C204 | D30: UI UX Design | E30: B1 | F30: Priya | G30: Mobile | H30: 7779 | I30: DISC10 | J30: 0.1 | K30: 9000 | L30: 45298
A31: S1029 | B31: Rohit Verma | C31: C203 | D31: Full Stack Dev | E31: B2 | F31: Priya | G31: Mobile | H31: 18538 | I31: DISC10 | J31: 0.1 | K31: 17000 | L31: 45335
A32: S1030 | B32: Rohit Singh | C32: C201 | D32: Data Analytics | E32: B1 | F32: Priya | G32: Tablet | H32: 13389 | I32: DISC10 | J32: 0.1 | K32: 14000 | L32: 45307
A33: S1031 | B33: Sneha Patil | C33: C204 | D33: UI UX Design | E33: B1 | F33: Priya | G33: Web | H33: 8140 | K33: 9000 | L33: 45307
A34: S1032 | B34: Meera Shah | C34: C204 | D34: UI UX Design | E34: B3 | F34: Saurabh | G34: Web | H34: 9671 | I34: DISC15 | K34: 9000 | L34: 45345
A35: S1033 | B35: Aarav Shah | C35: C202 | D35: Data Science | E35: B1 | F35: Priya | G35: Mobile | H35: 12971 | I35: DISC20 | J35: 0.2 | K35: 13000 | L35: 45347
A36: S1034 | B36: Rahul Kulkarni | C36: C202 | D36: Data Science | E36: B2 | F36: Saurabh | G36: Mobile | H36: 12086 | K36: 13000 | L36: 45310
A37: S1035 | B37: Rahul Desai | C37: C204 | D37: UI UX Design | E37: B1 | F37: Saurabh | G37: Mobile | H37: 7891 | I37: DISC10 | J37: 0.1 | K37: 9000 | L37: 45329
A38: S1036 | B38: Anjali Gupta | C38: C201 | D38: Data Analytics | E38: B3 | F38: Priya | G38: Web | H38: 12205 | I38: DISC15 | K38: 14000 | L38: 45322
A39: S1037 | B39: Manish Nair | C39: C202 | D39: Data Science | E39: B1 | F39: Amit | G39: Web | H39: 14487 | I39: DISC20 | J39: 0.2 | K39: 13000 | L39: 45296
A40: S1038 | B40: Kavita Shah | C40: C202 | D40: Data Science | E40: B2 | F40: Saurabh | G40: Tablet | H40: 12008 | I40: DISC15 | K40: 13000 | L40: 45330
...

Sheet Q10
A1: StudentID | B1: StudentName | C1: CourseID | D1: CourseName | E1: BatchID | F1: MentorName | G1: Platform | H1: PaymentAmount | I1: DiscountCode | J1: DiscountPercent | K1: TargetRevenue | L1: PaymentDate
A2: S1000 | B2: Rohit Shah | C2: C201 | D2: Data Analytics | E2: B3 | F2: Priya | G2: Web | H2: 12914 | I2: DISC20 | J2: 0.2 | K2: 14000 | L2: 45339
A3: S1001 | B3: Riya Singh | C3: C201 | D3: Data Analytics | E3: B3 | F3: Priya | G3: Web | H3: 12122 | I3: DISC10 | J3: 0.1 | K3: 14000 | L3: 45305 | N3: StudentID | O3: StudentName | P3: CourseID | Q3: CourseName | R3: BatchID | S3: MentorName | T3: Platform | U3: PaymentAmount | V3: DiscountCode | W3: DiscountPercent | X3: TargetRevenue | Y3: PaymentDate
A4: S1002 | B4: Sneha Gupta | C4: C201 | D4: Data Analytics | E4: B3 | F4: Saurabh | G4: Tablet | H4: 14661 | I4: DISC15 | K4: 14000 | L4: 45318 | N4: S1002 | O4: {=_xlfn.XLOOKUP(N4, Table1[StudentID], Table1[[StudentName]:[PaymentDate]])} -> Sneha Gupta | P4: C201 | Q4: Data Analytics | R4: B3 | S4: Saurabh | T4: Tablet | U4: 14661 | V4: DISC15 | W4: 0 | X4: 14000 | Y4: 45318
A5: S1003 | B5: Sneha Iyer | C5: C203 | D5: Full Stack Dev | E5: B1 | F5: Saurabh | G5: Tablet | H5: 16731 | I5: DISC30 | J5: 0.3 | K5: 17000 | L5: 45309
A6: S1004 | B6: Karan Patil | C6: C203 | D6: Full Stack Dev | E6: B1 | F6: Saurabh | G6: Mobile | H6: 15396 | I6: DISC30 | J6: 0.3 | K6: 17000 | L6: 45346
A7: S1005 | B7: Pooja Joshi | C7: C203 | D7: Full Stack Dev | E7: B1 | F7: Amit | G7: Mobile | H7: 17196 | I7: DISC10 | J7: 0.1 | K7: 17000 | L7: 45351
A8: S1006 | B8: Rahul Shah | C8: C203 | D8: Full Stack Dev | E8: B3 | F8: Amit | G8: Mobile | H8: 17364 | I8: DISC20 | J8: 0.2 | K8: 17000 | L8: 45337
A9: S1007 | B9: Riya Kulkarni | C9: C202 | D9: Data Science | E9: B2 | F9: Saurabh | G9: Web | H9: 14549 | I9: DISC10 | J9: 0.1 | K9: 13000 | L9: 45316
A10: S1008 | B10: Aditya Iyer | C10: C203 | D10: Full Stack Dev | E10: B1 | F10: Priya | G10: Mobile | H10: 15858 | I10: DISC30 | J10: 0.3 | K10: 17000 | L10: 45336
A11: S1009 | B11: Kunal Singh | C11: C201 | D11: Data Analytics | E11: B3 | F11: Amit | G11: Web | H11: 14187 | I11: DISC20 | J11: 0.2 | K11: 14000 | L11: 45302
A12: S1010 | B12: Neha Verma | C12: C203 | D12: Full Stack Dev | E12: B3 | F12: Amit | G12: Tablet | H12: 15899 | I12: DISC30 | J12: 0.3 | K12: 17000 | L12: 45345
A13: S1011 | B13: Dev Patel | C13: C201 | D13: Data Analytics | E13: B1 | F13: Saurabh | G13: Mobile | H13: 13643 | I13: DISC30 | J13: 0.3 | K13: 14000 | L13: 45296
A14: S1012 | B14: Sneha Joshi | C14: C203 | D14: Full Stack Dev | E14: B1 | F14: Amit | G14: Mobile | H14: 16620 | K14: 17000 | L14: 45301
A15: S1013 | B15: Aditya Mehta | C15: C202 | D15: Data Science | E15: B3 | F15: Amit | G15: Tablet | H15: 12076 | I15: DISC15 | K15: 13000 | L15: 45319
A16: S1014 | B16: Kunal Joshi | C16: C204 | D16: UI UX Design | E16: B2 | F16: Saurabh | G16: Web | H16: 9087 | K16: 9000 | L16: 45297
A17: S1015 | B17: Dev Kulkarni | C17: C201 | D17: Data Analytics | E17: B1 | F17: Amit | G17: Web | H17: 15244 | K17: 14000 | L17: 45330
A18: S1016 | B18: Riya Verma | C18: C204 | D18: UI UX Design | E18: B3 | F18: Priya | G18: Tablet | H18: 8029 | I18: DISC15 | K18: 9000 | L18: 45347
A19: S1017 | B19: Aarav Singh | C19: C201 | D19: Data Analytics | E19: B3 | F19: Amit | G19: Mobile | H19: 15148 | I19: DISC30 | J19: 0.3 | K19: 14000 | L19: 45299
A20: S1018 | B20: Aditya Verma | C20: C202 | D20: Data Science | E20: B2 | F20: Saurabh | G20: Tablet | H20: 14587 | I20: DISC30 | J20: 0.3 | K20: 13000 | L20: 45324
A21: S1019 | B21: Dev Mehta | C21: C201 | D21: Data Analytics | E21: B3 | F21: Priya | G21: Tablet | H21: 14079 | I21: DISC15 | K21: 14000 | L21: 45304
A22: S1020 | B22: Karan Jain | C22: C202 | D22: Data Science | E22: B3 | F22: Amit | G22: Web | H22: 13453 | I22: DISC30 | J22: 0.3 | K22: 13000 | L22: 45323
A23: S1021 | B23: Aarav Shah | C23: C203 | D23: Full Stack Dev | E23: B2 | F23: Saurabh | G23: Web | H23: 15986 | I23: DISC15 | K23: 17000 | L23: 45352
A24: S1022 | B24: Riya Shah | C24: C204 | D24: UI UX Design | E24: B1 | F24: Amit | G24: Web | H24: 7525 | K24: 9000 | L24: 45352
A25: S1023 | B25: Manish Mehta | C25: C203 | D25: Full Stack Dev | E25: B3 | F25: Amit | G25: Mobile | H25: 18950 | I25: DISC20 | J25: 0.2 | K25: 17000 | L25: 45351
A26: S1024 | B26: Manish Patel | C26: C202 | D26: Data Science | E26: B3 | F26: Priya | G26: Mobile | H26: 13751 | I26: DISC30 | J26: 0.3 | K26: 13000 | L26: 45320
A27: S1025 | B27: Kunal Gupta | C27: C204 | D27: UI UX Design | E27: B1 | F27: Saurabh | G27: Web | H27: 7262 | I27: DISC30 | J27: 0.3 | K27: 9000 | L27: 45293
A28: S1026 | B28: Kavita Gupta | C28: C202 | D28: Data Science | E28: B3 | F28: Saurabh | G28: Web | H28: 11290 | I28: DISC10 | J28: 0.1 | K28: 13000 | L28: 45306
A29: S1027 | B29: Riya Kulkarni | C29: C203 | D29: Full Stack Dev | E29: B1 | F29: Amit | G29: Web | H29: 16140 | K29: 17000 | L29: 45305
A30: S1028 | B30: Manish Mehta | C30: C204 | D30: UI UX Design | E30: B1 | F30: Priya | G30: Mobile | H30: 7779 | I30: DISC10 | J30: 0.1 | K30: 9000 | L30: 45298
A31: S1029 | B31: Rohit Verma | C31: C203 | D31: Full Stack Dev | E31: B2 | F31: Priya | G31: Mobile | H31: 18538 | I31: DISC10 | J31: 0.1 | K31: 17000 | L31: 45335
A32: S1030 | B32: Rohit Singh | C32: C201 | D32: Data Analytics | E32: B1 | F32: Priya | G32: Tablet | H32: 13389 | I32: DISC10 | J32: 0.1 | K32: 14000 | L32: 45307
A33: S1031 | B33: Sneha Patil | C33: C204 | D33: UI UX Design | E33: B1 | F33: Priya | G33: Web | H33: 8140 | K33: 9000 | L33: 45307
A34: S1032 | B34: Meera Shah | C34: C204 | D34: UI UX Design | E34: B3 | F34: Saurabh | G34: Web | H34: 9671 | I34: DISC15 | K34: 9000 | L34: 45345
A35: S1033 | B35: Aarav Shah | C35: C202 | D35: Data Science | E35: B1 | F35: Priya | G35: Mobile | H35: 12971 | I35: DISC20 | J35: 0.2 | K35: 13000 | L35: 45347
A36: S1034 | B36: Rahul Kulkarni | C36: C202 | D36: Data Science | E36: B2 | F36: Saurabh | G36: Mobile | H36: 12086 | K36: 13000 | L36: 45310
A37: S1035 | B37: Rahul Desai | C37: C204 | D37: UI UX Design | E37: B1 | F37: Saurabh | G37: Mobile | H37: 7891 | I37: DISC10 | J37: 0.1 | K37: 9000 | L37: 45329
A38: S1036 | B38: Anjali Gupta | C38: C201 | D38: Data Analytics | E38: B3 | F38: Priya | G38: Web | H38: 12205 | I38: DISC15 | K38: 14000 | L38: 45322
A39: S1037 | B39: Manish Nair | C39: C202 | D39: Data Science | E39: B1 | F39: Amit | G39: Web | H39: 14487 | I39: DISC20 | J39: 0.2 | K39: 13000 | L39: 45296
A40: S1038 | B40: Kavita Shah | C40: C202 | D40: Data Science | E40: B2 | F40: Saurabh | G40: Tablet | H40: 12008 | I40: DISC15 | K40: 13000 | L40: 45330
...

Sheet Q11
A1: StudentID | B1: StudentName | C1: CourseID | D1: CourseName | E1: BatchID | F1: MentorName | G1: Platform | H1: PaymentAmount | I1: DiscountCode | J1: DiscountPercent | K1: TargetRevenue | L1: PaymentDate
A2: S1000 | B2: Rohit Shah | C2: C201 | D2: Data Analytics | E2: B3 | F2: Priya | G2: Web | H2: 12914 | I2: DISC20 | J2: 0.2 | K2: 14000 | L2: 45339 | N2: Sum of PaymentAmount
A3: S1001 | B3: Riya Singh | C3: C201 | D3: Data Analytics | E3: B3 | F3: Priya | G3: Web | H3: 12122 | I3: DISC10 | J3: 0.1 | K3: 14000 | L3: 45305 | O3: Mobile | P3: Tablet | Q3: Web | R3: Grand Total
A4: S1002 | B4: Sneha Gupta | C4: C201 | D4: Data Analytics | E4: B3 | F4: Saurabh | G4: Tablet | H4: 14661 | I4: DISC15 | K4: 14000 | L4: 45318 | N4: Data Analytics | O4: 1119871 | P4: 1458981 | Q4: 928879 | R4: 3507731
A5: S1003 | B5: Sneha Iyer | C5: C203 | D5: Full Stack Dev | E5: B1 | F5: Saurabh | G5: Tablet | H5: 16731 | I5: DISC30 | J5: 0.3 | K5: 17000 | L5: 45309 | N5: Data Science | O5: 1167543 | P5: 921127 | Q5: 1067078 | R5: 3155748
A6: S1004 | B6: Karan Patil | C6: C203 | D6: Full Stack Dev | E6: B1 | F6: Saurabh | G6: Mobile | H6: 15396 | I6: DISC30 | J6: 0.3 | K6: 17000 | L6: 45346 | N6: Full Stack Dev | O6: 1348435 | P6: 1729206 | Q6: 1462566 | R6: 4540207
A7: S1005 | B7: Pooja Joshi | C7: C203 | D7: Full Stack Dev | E7: B1 | F7: Amit | G7: Mobile | H7: 17196 | I7: DISC10 | J7: 0.1 | K7: 17000 | L7: 45351 | N7: UI UX Design | O7: 660619 | P7: 792176 | Q7: 738812 | R7: 2191607
A8: S1006 | B8: Rahul Shah | C8: C203 | D8: Full Stack Dev | E8: B3 | F8: Amit | G8: Mobile | H8: 17364 | I8: DISC20 | J8: 0.2 | K8: 17000 | L8: 45337 | N8: Grand Total | O8: 4296468 | P8: 4901490 | Q8: 4197335 | R8: 13395293
A9: S1007 | B9: Riya Kulkarni | C9: C202 | D9: Data Science | E9: B2 | F9: Saurabh | G9: Web | H9: 14549 | I9: DISC10 | J9: 0.1 | K9: 13000 | L9: 45316
A10: S1008 | B10: Aditya Iyer | C10: C203 | D10: Full Stack Dev | E10: B1 | F10: Priya | G10: Mobile | H10: 15858 | I10: DISC30 | J10: 0.3 | K10: 17000 | L10: 45336
A11: S1009 | B11: Kunal Singh | C11: C201 | D11: Data Analytics | E11: B3 | F11: Amit | G11: Web | H11: 14187 | I11: DISC20 | J11: 0.2 | K11: 14000 | L11: 45302
A12: S1010 | B12: Neha Verma | C12: C203 | D12: Full Stack Dev | E12: B3 | F12: Amit | G12: Tablet | H12: 15899 | I12: DISC30 | J12: 0.3 | K12: 17000 | L12: 45345
A13: S1011 | B13: Dev Patel | C13: C201 | D13: Data Analytics | E13: B1 | F13: Saurabh | G13: Mobile | H13: 13643 | I13: DISC30 | J13: 0.3 | K13: 14000 | L13: 45296
A14: S1012 | B14: Sneha Joshi | C14: C203 | D14: Full Stack Dev | E14: B1 | F14: Amit | G14: Mobile | H14: 16620 | K14: 17000 | L14: 45301
A15: S1013 | B15: Aditya Mehta | C15: C202 | D15: Data Science | E15: B3 | F15: Amit | G15: Tablet | H15: 12076 | I15: DISC15 | K15: 13000 | L15: 45319
A16: S1014 | B16: Kunal Joshi | C16: C204 | D16: UI UX Design | E16: B2 | F16: Saurabh | G16: Web | H16: 9087 | K16: 9000 | L16: 45297
A17: S1015 | B17: Dev Kulkarni | C17: C201 | D17: Data Analytics | E17: B1 | F17: Amit | G17: Web | H17: 15244 | K17: 14000 | L17: 45330
A18: S1016 | B18: Riya Verma | C18: C204 | D18: UI UX Design | E18: B3 | F18: Priya | G18: Tablet | H18: 8029 | I18: DISC15 | K18: 9000 | L18: 45347
A19: S1017 | B19: Aarav Singh | C19: C201 | D19: Data Analytics | E19: B3 | F19: Amit | G19: Mobile | H19: 15148 | I19: DISC30 | J19: 0.3 | K19: 14000 | L19: 45299
A20: S1018 | B20: Aditya Verma | C20: C202 | D20: Data Science | E20: B2 | F20: Saurabh | G20: Tablet | H20: 14587 | I20: DISC30 | J20: 0.3 | K20: 13000 | L20: 45324
A21: S1019 | B21: Dev Mehta | C21: C201 | D21: Data Analytics | E21: B3 | F21: Priya | G21: Tablet | H21: 14079 | I21: DISC15 | K21: 14000 | L21: 45304
A22: S1020 | B22: Karan Jain | C22: C202 | D22: Data Science | E22: B3 | F22: Amit | G22: Web | H22: 13453 | I22: DISC30 | J22: 0.3 | K22: 13000 | L22: 45323
A23: S1021 | B23: Aarav Shah | C23: C203 | D23: Full Stack Dev | E23: B2 | F23: Saurabh | G23: Web | H23: 15986 | I23: DISC15 | K23: 17000 | L23: 45352
A24: S1022 | B24: Riya Shah | C24: C204 | D24: UI UX Design | E24: B1 | F24: Amit | G24: Web | H24: 7525 | K24: 9000 | L24: 45352
A25: S1023 | B25: Manish Mehta | C25: C203 | D25: Full Stack Dev | E25: B3 | F25: Amit | G25: Mobile | H25: 18950 | I25: DISC20 | J25: 0.2 | K25: 17000 | L25: 45351
A26: S1024 | B26: Manish Patel | C26: C202 | D26: Data Science | E26: B3 | F26: Priya | G26: Mobile | H26: 13751 | I26: DISC30 | J26: 0.3 | K26: 13000 | L26: 45320
A27: S1025 | B27: Kunal Gupta | C27: C204 | D27: UI UX Design | E27: B1 | F27: Saurabh | G27: Web | H27: 7262 | I27: DISC30 | J27: 0.3 | K27: 9000 | L27: 45293
A28: S1026 | B28: Kavita Gupta | C28: C202 | D28: Data Science | E28: B3 | F28: Saurabh | G28: Web | H28: 11290 | I28: DISC10 | J28: 0.1 | K28: 13000 | L28: 45306
A29: S1027 | B29: Riya Kulkarni | C29: C203 | D29: Full Stack Dev | E29: B1 | F29: Amit | G29: Web | H29: 16140 | K29: 17000 | L29: 45305
A30: S1028 | B30: Manish Mehta | C30: C204 | D30: UI UX Design | E30: B1 | F30: Priya | G30: Mobile | H30: 7779 | I30: DISC10 | J30: 0.1 | K30: 9000 | L30: 45298
A31: S1029 | B31: Rohit Verma | C31: C203 | D31: Full Stack Dev | E31: B2 | F31: Priya | G31: Mobile | H31: 18538 | I31: DISC10 | J31: 0.1 | K31: 17000 | L31: 45335
A32: S1030 | B32: Rohit Singh | C32: C201 | D32: Data Analytics | E32: B1 | F32: Priya | G32: Tablet | H32: 13389 | I32: DISC10 | J32: 0.1 | K32: 14000 | L32: 45307
A33: S1031 | B33: Sneha Patil | C33: C204 | D33: UI UX Design | E33: B1 | F33: Priya | G33: Web | H33: 8140 | K33: 9000 | L33: 45307
A34: S1032 | B34: Meera Shah | C34: C204 | D34: UI UX Design | E34: B3 | F34: Saurabh | G34: Web | H34: 9671 | I34: DISC15 | K34: 9000 | L34: 45345
A35: S1033 | B35: Aarav Shah | C35: C202 | D35: Data Science | E35: B1 | F35: Priya | G35: Mobile | H35: 12971 | I35: DISC20 | J35: 0.2 | K35: 13000 | L35: 45347
A36: S1034 | B36: Rahul Kulkarni | C36: C202 | D36: Data Science | E36: B2 | F36: Saurabh | G36: Mobile | H36: 12086 | K36: 13000 | L36: 45310
A37: S1035 | B37: Rahul Desai | C37: C204 | D37: UI UX Design | E37: B1 | F37: Saurabh | G37: Mobile | H37: 7891 | I37: DISC10 | J37: 0.1 | K37: 9000 | L37: 45329
A38: S1036 | B38: Anjali Gupta | C38: C201 | D38: Data Analytics | E38: B3 | F38: Priya | G38: Web | H38: 12205 | I38: DISC15 | K38: 14000 | L38: 45322
A39: S1037 | B39: Manish Nair | C39: C202 | D39: Data Science | E39: B1 | F39: Amit | G39: Web | H39: 14487 | I39: DISC20 | J39: 0.2 | K39: 13000 | L39: 45296
A40: S1038 | B40: Kavita Shah | C40: C202 | D40: Data Science | E40: B2 | F40: Saurabh | G40: Tablet | H40: 12008 | I40: DISC15 | K40: 13000 | L40: 45330
...

Sheet Q12
A1: StudentID | B1: StudentName | C1: CourseID | D1: CourseName | E1: BatchID | F1: MentorName | G1: Platform | H1: PaymentAmount | I1: DiscountCode | J1: DiscountPercent | K1: TargetRevenue | L1: PaymentDate | N1: Sum of Net Revenue
A2: S1000 | B2: Rohit Shah | C2: C201 | D2: Data Analytics | E2: B3 | F2: Priya | G2: Web | H2: 12914 | I2: DISC20 | J2: 0.2 | K2: 14000 | L2: 45339 | N2: -1.6208305e+09
A3: S1001 | B3: Riya Singh | C3: C201 | D3: Data Analytics | E3: B3 | F3: Priya | G3: Web | H3: 12122 | I3: DISC10 | J3: 0.1 | K3: 14000 | L3: 45305
A4: S1002 | B4: Sneha Gupta | C4: C201 | D4: Data Analytics | E4: B3 | F4: Saurabh | G4: Tablet | H4: 14661 | I4: DISC15 | K4: 14000 | L4: 45318
A5: S1003 | B5: Sneha Iyer | C5: C203 | D5: Full Stack Dev | E5: B1 | F5: Saurabh | G5: Tablet | H5: 16731 | I5: DISC30 | J5: 0.3 | K5: 17000 | L5: 45309
A6: S1004 | B6: Karan Patil | C6: C203 | D6: Full Stack Dev | E6: B1 | F6: Saurabh | G6: Mobile | H6: 15396 | I6: DISC30 | J6: 0.3 | K6: 17000 | L6: 45346
A7: S1005 | B7: Pooja Joshi | C7: C203 | D7: Full Stack Dev | E7: B1 | F7: Amit | G7: Mobile | H7: 17196 | I7: DISC10 | J7: 0.1 | K7: 17000 | L7: 45351
A8: S1006 | B8: Rahul Shah | C8: C203 | D8: Full Stack Dev | E8: B3 | F8: Amit | G8: Mobile | H8: 17364 | I8: DISC20 | J8: 0.2 | K8: 17000 | L8: 45337
A9: S1007 | B9: Riya Kulkarni | C9: C202 | D9: Data Science | E9: B2 | F9: Saurabh | G9: Web | H9: 14549 | I9: DISC10 | J9: 0.1 | K9: 13000 | L9: 45316
A10: S1008 | B10: Aditya Iyer | C10: C203 | D10: Full Stack Dev | E10: B1 | F10: Priya | G10: Mobile | H10: 15858 | I10: DISC30 | J10: 0.3 | K10: 17000 | L10: 45336
A11: S1009 | B11: Kunal Singh | C11: C201 | D11: Data Analytics | E11: B3 | F11: Amit | G11: Web | H11: 14187 | I11: DISC20 | J11: 0.2 | K11: 14000 | L11: 45302
A12: S1010 | B12: Neha Verma | C12: C203 | D12: Full Stack Dev | E12: B3 | F12: Amit | G12: Tablet | H12: 15899 | I12: DISC30 | J12: 0.3 | K12: 17000 | L12: 45345
A13: S1011 | B13: Dev Patel | C13: C201 | D13: Data Analytics | E13: B1 | F13: Saurabh | G13: Mobile | H13: 13643 | I13: DISC30 | J13: 0.3 | K13: 14000 | L13: 45296
A14: S1012 | B14: Sneha Joshi | C14: C203 | D14: Full Stack Dev | E14: B1 | F14: Amit | G14: Mobile | H14: 16620 | K14: 17000 | L14: 45301
A15: S1013 | B15: Aditya Mehta | C15: C202 | D15: Data Science | E15: B3 | F15: Amit | G15: Tablet | H15: 12076 | I15: DISC15 | K15: 13000 | L15: 45319
A16: S1014 | B16: Kunal Joshi | C16: C204 | D16: UI UX Design | E16: B2 | F16: Saurabh | G16: Web | H16: 9087 | K16: 9000 | L16: 45297
A17: S1015 | B17: Dev Kulkarni | C17: C201 | D17: Data Analytics | E17: B1 | F17: Amit | G17: Web | H17: 15244 | K17: 14000 | L17: 45330
A18: S1016 | B18: Riya Verma | C18: C204 | D18: UI UX Design | E18: B3 | F18: Priya | G18: Tablet | H18: 8029 | I18: DISC15 | K18: 9000 | L18: 45347
A19: S1017 | B19: Aarav Singh | C19: C201 | D19: Data Analytics | E19: B3 | F19: Amit | G19: Mobile | H19: 15148 | I19: DISC30 | J19: 0.3 | K19: 14000 | L19: 45299
A20: S1018 | B20: Aditya Verma | C20: C202 | D20: Data Science | E20: B2 | F20: Saurabh | G20: Tablet | H20: 14587 | I20: DISC30 | J20: 0.3 | K20: 13000 | L20: 45324
A21: S1019 | B21: Dev Mehta | C21: C201 | D21: Data Analytics | E21: B3 | F21: Priya | G21: Tablet | H21: 14079 | I21: DISC15 | K21: 14000 | L21: 45304
A22: S1020 | B22: Karan Jain | C22: C202 | D22: Data Science | E22: B3 | F22: Amit | G22: Web | H22: 13453 | I22: DISC30 | J22: 0.3 | K22: 13000 | L22: 45323
A23: S1021 | B23: Aarav Shah | C23: C203 | D23: Full Stack Dev | E23: B2 | F23: Saurabh | G23: Web | H23: 15986 | I23: DISC15 | K23: 17000 | L23: 45352
A24: S1022 | B24: Riya Shah | C24: C204 | D24: UI UX Design | E24: B1 | F24: Amit | G24: Web | H24: 7525 | K24: 9000 | L24: 45352
A25: S1023 | B25: Manish Mehta | C25: C203 | D25: Full Stack Dev | E25: B3 | F25: Amit | G25: Mobile | H25: 18950 | I25: DISC20 | J25: 0.2 | K25: 17000 | L25: 45351
A26: S1024 | B26: Manish Patel | C26: C202 | D26: Data Science | E26: B3 | F26: Priya | G26: Mobile | H26: 13751 | I26: DISC30 | J26: 0.3 | K26: 13000 | L26: 45320
A27: S1025 | B27: Kunal Gupta | C27: C204 | D27: UI UX Design | E27: B1 | F27: Saurabh | G27: Web | H27: 7262 | I27: DISC30 | J27: 0.3 | K27: 9000 | L27: 45293
A28: S1026 | B28: Kavita Gupta | C28: C202 | D28: Data Science | E28: B3 | F28: Saurabh | G28: Web | H28: 11290 | I28: DISC10 | J28: 0.1 | K28: 13000 | L28: 45306
A29: S1027 | B29: Riya Kulkarni | C29: C203 | D29: Full Stack Dev | E29: B1 | F29: Amit | G29: Web | H29: 16140 | K29: 17000 | L29: 45305
A30: S1028 | B30: Manish Mehta | C30: C204 | D30: UI UX Design | E30: B1 | F30: Priya | G30: Mobile | H30: 7779 | I30: DISC10 | J30: 0.1 | K30: 9000 | L30: 45298
A31: S1029 | B31: Rohit Verma | C31: C203 | D31: Full Stack Dev | E31: B2 | F31: Priya | G31: Mobile | H31: 18538 | I31: DISC10 | J31: 0.1 | K31: 17000 | L31: 45335
A32: S1030 | B32: Rohit Singh | C32: C201 | D32: Data Analytics | E32: B1 | F32: Priya | G32: Tablet | H32: 13389 | I32: DISC10 | J32: 0.1 | K32: 14000 | L32: 45307
A33: S1031 | B33: Sneha Patil | C33: C204 | D33: UI UX Design | E33: B1 | F33: Priya | G33: Web | H33: 8140 | K33: 9000 | L33: 45307
A34: S1032 | B34: Meera Shah | C34: C204 | D34: UI UX Design | E34: B3 | F34: Saurabh | G34: Web | H34: 9671 | I34: DISC15 | K34: 9000 | L34: 45345
A35: S1033 | B35: Aarav Shah | C35: C202 | D35: Data Science | E35: B1 | F35: Priya | G35: Mobile | H35: 12971 | I35: DISC20 | J35: 0.2 | K35: 13000 | L35: 45347
A36: S1034 | B36: Rahul Kulkarni | C36: C202 | D36: Data Science | E36: B2 | F36: Saurabh | G36: Mobile | H36: 12086 | K36: 13000 | L36: 45310
A37: S1035 | B37: Rahul Desai | C37: C204 | D37: UI UX Design | E37: B1 | F37: Saurabh | G37: Mobile | H37: 7891 | I37: DISC10 | J37: 0.1 | K37: 9000 | L37: 45329
A38: S1036 | B38: Anjali Gupta | C38: C201 | D38: Data Analytics | E38: B3 | F38: Priya | G38: Web | H38: 12205 | I38: DISC15 | K38: 14000 | L38: 45322
A39: S1037 | B39: Manish Nair | C39: C202 | D39: Data Science | E39: B1 | F39: Amit | G39: Web | H39: 14487 | I39: DISC20 | J39: 0.2 | K39: 13000 | L39: 45296
A40: S1038 | B40: Kavita Shah | C40: C202 | D40: Data Science | E40: B2 | F40: Saurabh | G40: Tablet | H40: 12008 | I40: DISC15 | K40: 13000 | L40: 45330
...

Sheet Q13
A1: Sales & Course Revenue Analytics Dashboard
A30: StudentID | B30: StudentName | C30: CourseID | D30: CourseName | E30: BatchID | F30: MentorName | G30: Platform | H30: PaymentAmount | I30: DiscountCode | J30: DiscountPercent | K30: TargetRevenue | L30: PaymentDate | M30: Performance Status | O30: Row Labels | P30: Sum of PaymentAmount
A31: S1000 | B31: Rohit Shah | C31: C201 | D31: Data Analytics | E31: B3 | F31: Priya | G31: Web | H31: 12914 | I31: DISC20 | J31: 0.2 | K31: 14000 | L31: 45339 | M31: =IF(H31>=K31,"Target Achieved","Below Target") -> Below Target | O31: Data Analytics | P31: 3507731
A32: S1001 | B32: Riya Singh | C32: C201 | D32: Data Analytics | E32: B3 | F32: Priya | G32: Web | H32: 12122 | I32: DISC10 | J32: 0.1 | K32: 14000 | L32: 45305 | M32: =IF(H32>=K32,"Target Achieved","Below Target") -> Below Target | O32: Data Science | P32: 3155748
A33: S1002 | B33: Sneha Gupta | C33: C201 | D33: Data Analytics | E33: B3 | F33: Saurabh | G33: Tablet | H33: 14661 | I33: DISC15 | K33: 14000 | L33: 45318 | M33: =IF(H33>=K33,"Target Achieved","Below Target") -> Target Achieved | O33: Full Stack Dev | P33: 4540207
A34: S1003 | B34: Sneha Iyer | C34: C203 | D34: Full Stack Dev | E34: B1 | F34: Saurabh | G34: Tablet | H34: 16731 | I34: DISC30 | J34: 0.3 | K34: 17000 | L34: 45309 | M34: =IF(H34>=K34,"Target Achieved","Below Target") -> Below Target | O34: UI UX Design | P34: 2191607
